Workbook

Sheet cara pakai
C3: Berikut penjelasan detail cara pakai:
C5: 1) Scenario Manager (A/B/C)
C7: Buka sheet “Scenarios”: ada tiga skenario default (A/B/C) berisi VC/unit, FC/bulan, fee%, PPN%, target margin%, volume target, dan Diskon%.
C9: Di sheet “Inputs”, pilih skenario di sel B3 (dropdown). Semua parameter otomatis tersalin ke bagian bawah “Terpilih dari Scenario Manager”.
C11: Kamu tetap bisa isi biaya manual (VC/FC rinci). Model akan mengutamakan angka manual jika diisi (otomatis mem-bypass skenario).
C13: 2) Parameter Diskon/Promo
C15: Diskon (%) ada di skenario dan bisa ditimpa manual di Inputs → Parameter Komersial.
C17: Di sheet “Pricing-Model”:
C21: P_net (list): harga neto sebelum diskon.
C23: P_net (transaksi): P_net(list) × (1 − diskon) → harga real untuk hitung margin.
C25: CM/unit menggunakan P_net (transaksi) → P_net(tx) × (1 − fee) − VC.
C27: BEP (unit) = FC / CM (berbasis harga setelah diskon).
... C78: 4. Lihat grafik untuk gambaran visual profit vs volume dan posisi BEP.

Sheet Scenarios
A1: Scenario Manager (A/B/C)
A3: Nama | B3: VC per Unit | C3: FC per Bulan | D3: Fee % | E3: PPN % | F3: Target Margin % (atas P_net) | G3: Volume Target | H3: Diskon %
A4: A | B4: 155000 | C4: 30000000 | D4: 12 | E4: 11 | F4: 40 | G4: 300 | H4: 0
A5: B | B5: 165000 | C5: 28000000 | D5: 10 | E5: 11 | F5: 35 | G5: 400 | H5: 5
A6: C | B6: 140000 | C6: 35000000 | D6: 15 | E6: 11 | F6: 45 | G6: 250 | H6: 10

Sheet Inputs
A1: INPUTS — Rincian Biaya Tetap & Variabel + Pilih Skenario
A3: Pilih Skenario (A/B/C) | B3: A
A5: Variable Cost per Unit (editable)
A6: Item | B6: Biaya/Unit (Rp)
A7: Bahan baku
A8: Tenaga kerja langsung (TKL)
A9: Kemasan
A10: Logistik per unit
A11: Biaya variabel lain
A12: TOTAL VC / Unit (manual) | B12: =SUM(B7:B11) -> 0
A14: Fixed Cost per Bulan (editable)
A15: Item | B15: Biaya/Bulan (Rp)
A16: Sewa
A17: Gaji staf tetap
A18: Penyusutan & amortisasi
A19: Utilitas & internet
A20: Asuransi & perizinan
A21: Overhead tetap lain
A22: TOTAL FC / Bulan (manual) | B22: =SUM(B16:B21) -> 0
A24: Parameter Komersial
A25: Fee kanal (%)
A26: PPN (%)
A27: Target margin (%) atas P_net
A28: Volume target (unit/bulan)
A29: Diskon (%)
A32: Terpilih dari Scenario Manager (otomatis)
A33: VC/Unit (scenario) | B33: =INDEX(Scenarios!$B$4:$B$6, MATCH($B$3, Scenarios!$A$4:$A$6, 0)) -> 155000
A34: FC/Bulan (scenario) | B34: =INDEX(Scenarios!$C$4:$C$6, MATCH($B$3, Scenarios!$A$4:$A$6, 0)) -> 30000000
A35: Fee% (scenario) | B35: =INDEX(Scenarios!$D$4:$D$6, MATCH($B$3, Scenarios!$A$4:$A$6, 0)) -> 12
A36: PPN% (scenario) | B36: =INDEX(Scenarios!$E$4:$E$6, MATCH($B$3, Scenarios!$A$4:$A$6, 0)) -> 11
A37: Margin% (scenario) | B37: =INDEX(Scenarios!$F$4:$F$6, MATCH($B$3, Scenarios!$A$4:$A$6, 0)) -> 40
A38: Volume (scenario) | B38: =INDEX(Scenarios!$G$4:$G$6, MATCH($B$3, Scenarios!$A$4:$A$6, 0)) -> 300
A39: Diskon% (scenario) | B39: =INDEX(Scenarios!$H$4:$H$6, MATCH($B$3, Scenarios!$A$4:$A$6, 0)) -> 0
A41: Helper
A42: Fee (desimal) | B42: =IF(B27<>"", B27/100, B35/100) -> 0.12
A43: PPN (desimal) | B43: =IF(B28<>"", B28/100, B36/100) -> 0.11
A44: Margin (desimal) | B44: =IF(B29<>"", B29/100, B37/100) -> 0.4
A45: Diskon (desimal) | B45: =IF(B31<>"", B31/100, B39/100) -> 0
A47: VC pilih (manual jika ada, else scenario) | B47: =IF(B12<>0,B12,B33) -> 155000
A48: FC pilih (manual jika ada, else scenario) | B48: =IF(B22<>0,B22,B34) -> 30000000
...

Sheet Pricing-Model
A1: PRICING MODEL — VC/FC + Diskon + BEP + Profit vs Volume
A3: Ringkasan Biaya & Parameter (terpilih) | D3: Cost-Plus (P_net list) & Transaksional | H3: Volume | I3: Profit (Rp) | J3: Zero
A4: Variable Cost / Unit (VC) | B4: =Inputs!B47 -> 155000 | D4: P_net (list) | E4: =B4/(1-B6-B5) -> -0.0051666668 | H4: 0 | I4: =$E$8*H4 - $B$5 -> -30000000 | J4: 0
A5: Fixed Cost / Bulan (FC) | B5: =Inputs!B48 -> 30000000 | D5: P_gross (list) | E5: =E4*(1+B6) -> -0.0057866668 | H5: =ROUND($B$8/5,0) -> 0 | I5: =$E$8*H5 - $B$5 -> -30000000 | J5: 0
A6: Fee (desimal) | B6: =Inputs!B42 -> 0.12 | D6: P_net (transaksional) = P_net*(1-diskon) | E6: =E4*(1-B7) -> -0.0045983335 | H6: =H5+H5 -> 0 | I6: =$E$8*H6 - $B$5 -> -30000000 | J6: 0
A7: PPN (desimal) | B7: =Inputs!B43 -> 0.11 | D7: P_gross (transaksi) = P_net(tx)*(1+PPN) | E7: =E6*(1+B6) -> -0.0051501335 | H7: =H6+H5 -> 0 | I7: =$E$8*H7 - $B$5 -> -30000000 | J7: 0
A8: Margin (desimal) atas P_net | B8: =Inputs!B44 -> 0.4 | D8: CM/unit = P_net(tx)*(1-fee) − VC | E8: =E6*(1-B5)-B4 -> -17050.001 | H8: =H7+H5 -> 0 | I8: =$E$8*H8 - $B$5 -> -30000000 | J8: 0
A9: Diskon (desimal) | B9: =Inputs!B45 -> 0 | D9: BEP (unit/bulan) = FC / CM | E9: =B5/E8 -> -1759.5307 | H9: =H8+H5 -> 0 | I9: =$E$8*H9 - $B$5 -> -30000000 | J9: 0
A10: Volume target (unit/bulan) | B10: =Inputs!B49 -> 300 | H10: =H9+H5 -> 0 | I10: =$E$8*H10 - $B$5 -> -30000000 | J10: 0
A11: Unit Economics (berdasarkan harga transaksional) | H11: =H10+H5 -> 0 | I11: =$E$8*H11 - $B$5 -> -30000000 | J11: 0
A12: P_net (tx) | B12: =E6 -> -0.0045983335 | H12: =H11+H5 -> 0 | I12: =$E$8*H12 - $B$5 -> -30000000 | J12: 0
A13: Fee nominal/unit | B13: =E6*B5 -> -137950 | H13: =H12+H5 -> 0 | I13: =$E$8*H13 - $B$5 -> -30000000 | J13: 0
A14: Revenue setelah fee | B14: =E6*(1-B5) -> 137950 | H14: =H13+H5 -> 0 | I14: =$E$8*H14 - $B$5 -> -30000000 | J14: 0
A15: Variable Cost (VC) | B15: =B4 -> 155000 | H15: =H14+H5 -> 0 | I15: =$E$8*H15 - $B$5 -> -30000000 | J15: 0
A16: Contribution Margin (CM) | B16: =E6*(1-B5)-B4 -> -17050.001
A17: Alokasi FC per unit | B17: =B5/B8 -> 75000000
A18: Operating Profit per unit | B18: =B16-B17 -> -75017050
A19: P_gross (tx) | B19: =E7 -> -0.0051501335
A21: Laba/bln @ volume target | B21: =E8*B8 - B5 -> -30006820
A24: SKENARIO HARGA (isi P_gross list & Diskon %)
A25: P_gross (list) | B25: Diskon % | C25: P_net list | D25: P_net (tx) | E25: Revenue setelah fee | F25: CM/unit | G25: BEP (unit) | H25: Laba/bln @ volume target
A26: 359000 | B26: 0 | C26: =A26/(1+$B$6) -> 320535.71 | D26: =C26*(1-B26/100) -> 320535.71 | E26: =D26*(1-$B$5) -> -9.6160711e+12 | F26: =E26-$B$4 -> -9.6160713e+12 | G26: =$B$5/F26 -> -3.1197772e-06 | H26: =F26*$B$8-$B$5 -> -3.8464585e+12
A27: 365000 | B27: 0 | C27: =A27/(1+$B$6) -> 325892.86 | D27: =C27*(1-B27/100) -> 325892.86 | E27: =D27*(1-$B$5) -> -9.7767854e+12 | F27: =E27-$B$4 -> -9.7767855e+12 | G27: =$B$5/F27 -> -3.0684932e-06 | H27: =F27*$B$8-$B$5 -> -3.9107442e+12
A28: 399000 | B28: 5 | C28: =A28/(1+$B$6) -> 356250 | D28: =C28*(1-B28/100) -> 338437.5 | E28: =D28*(1-$B$5) -> -1.0153125e+13 | F28: =E28-$B$4 -> -1.0153125e+13 | G28: =$B$5/F28 -> -2.9547554e-06 | H28: =F28*$B$8-$B$5 -> -4.0612799e+12
